Workbook

Sheet IC Summary
A1: PMC PLATFORM — INVESTMENT COMMITTEE SUMMARY
A2: =" Base case shown unless a column is labelled otherwise. Controls: "&Controls!$B$77&" | "&Controls!$C$77&" | Release candidate v2.4.4, supervisor review then desktop Excel gate." -> Base case shown unless a column is labelled otherwise. Controls: 57 of 66 | REVIEW | Release candidate v2.4.4, supervisor review then desktop Excel gate.
A4: 1. WHAT WE ARE BUYING
A5: Anchor platform | C5: ='Acquisition Schedule'!F$6 -> 1000000
A6: Annual large tuck-ins, Years 1 to 7 | C6: =COUNTIF('Acquisition Schedule'!$B$6:$B$14,"Large tuck-in") -> 7
A7: Year-3 mid-market addition | C7: =INDEX(Assumptions!$D$37:$F$37,1,2) -> 1250000
A8: Total acquired EBITDA | C8: ='Acquisition Schedule'!F$15 -> 7500000
A9: Total acquisition enterprise value | C9: ='Acquisition Schedule'!N$15 -> 34500000
A10: Blended entry multiple | C10: =IF('Acquisition Schedule'!F$15=0,0,'Acquisition Schedule'!N$15/'Acquisition Schedule'!F$15) -> 4.6
A12: 2. SCALE AND RESULT
D13: Year 3 | E13: Year 5 | F13: Year 7 | G13: Year 10
A14: Managed units | D14: ='Operating Case'!G$50 -> 26492.36 | E14: ='Operating Case'!I$50 -> 44168.302 | F14: ='Operating Case'!K$50 -> 50000 | G14: ='Operating Case'!N$50 -> 50000
A15: Properties | D15: ='Operating Case'!G$51 -> 105.96944 | E15: ='Operating Case'!I$51 -> 176.67321 | F15: ='Operating Case'!K$51 -> 200 | G15: ='Operating Case'!N$51 -> 200
A16: Clients | D16: ='Operating Case'!G$52 -> 14.769785 | E16: ='Operating Case'!I$52 -> 24.875588 | F16: ='Operating Case'!K$52 -> 28.330667 | G16: ='Operating Case'!N$52 -> 28.330667
A17: Recurring revenue | D17: ='Operating Case'!G$54 -> 17312306 | E17: ='Operating Case'!I$54 -> 28863232 | F17: ='Operating Case'!K$54 -> 32674147 | G17: ='Operating Case'!N$54 -> 32674147
A18: Total platform revenue | D18: ='Operating Case'!G$54+'Operating Case'!G$50*INDEX(Assumptions!$D$30:$F$30,1,2)+'Operating Case'!G$67+'Operating Case'!G$69+'Operating Case'!G$71 -> 18054092 | E18: ='Operating Case'!I$54+'Operating Case'!I$50*INDEX(Assumptions!$D$30:$F$30,1,2)+'Operating Case'!I$67+'Operating Case'!I$69+'Operating Case'!I$71 -> 30099945 | F18: ='Operating Case'!K$54+'Operating Case'!K$50*INDEX(Assumptions!$D$30:$F$30,1,2)+'Operating Case'!K$67+'Operating Case'!K$69+'Operating Case'!K$71 -> 34074147 | G18: ='Operating Case'!N$54+'Operating Case'!N$50*INDEX(Assumptions!$D$30:$F$30,1,2)+'Operating Case'!N$67+'Operating Case'!N$69+'Operating Case'!N$71 -> 34074147
A19: Consolidated platform EBITDA | D19: ='Operating Case'!G$79 -> -645223.17 | E19: ='Operating Case'!I$79 -> 1989260.4 | F19: ='Operating Case'!K$79 -> 2910357.8 | G19: ='Operating Case'!N$79 -> 1641331.6
A20: Platform EBITDA margin | D20: ='Operating Case'!G$88 -> -0.035738335 | E20: ='Operating Case'!I$88 -> 0.066088507 | F20: ='Operating Case'!K$88 -> 0.085412491 | G20: ='Operating Case'!N$88 -> 0.048169412
A22: 3. WHERE THE YEAR-7 EBITDA COMES FROM
A23: Acquired book — contracted EBITDA | C23: ='Operating Case'!K$55 -> 5171512 | E23: ACQUIRED / RECURRING
A24: Organic new business | C24: ='Operating Case'!K$56 -> 1228488 | E24: BUYER-CREATED / REVENUE
A25: Centralisation — seller payroll removed | C25: ='Operating Case'!K$58 -> 8528944.6 | E25: BUYER-CREATED / COST
A26: less same-scope shared-services replacement | C26: =-'Org & Capacity'!$D$245 -> -3622536.8 | E26: BUYER-CREATED / COST
A27: of which nearshore delivery saving (memo) | C27: ='Org & Capacity'!$D$259 -> 1532367.6 | E27: MEMO — inside the two lines above
A28: Leadership redundancy — uncredited by decision | C28: ='Operating Case'!K$61 -> 0 | E28: [OQ] UNCREDITED UPSIDE
A29: New-function institutionalisation | C29: =-'Org & Capacity'!$D$247 -> -2547285.7 | E29: BUYER-CREATED / COST
A30: Organic-growth support capacity | C30: =-'Org & Capacity'!$D$249 -> -986816.58 | E30: BUYER-CREATED / COST
A31: Transition overlap, complexity and integration | C31: ='Operating Case'!K$60+'Operating Case'!K$62+'Operating Case'!K$64+'Operating Case'!K$65 -> -1480941.8 | E31: BUYER-CREATED / COST
A32: Platform services — Layers 1 to 3, net | C32: ='Operating Case'!K$67+'Operating Case'!K$68+'Operating Case'!K$69+'Operating Case'!K$70+'Operating Case'!K$71+'Operating Case'!K$72+'Operating Case'!K$63+'Operating Case'!K$73 -> -415602.31 | E32: BUYER-CREATED / REVENUE
A33: HoldCo payroll and non-payroll G&A | C33: ='Operating Case'!K$77+'Operating Case'!K$78 -> -2965403.6 | E33: BUYER-CREATED / COST
A34: CONSOLIDATED PLATFORM EBITDA — YEAR 7 | C34: ='Operating Case'!K$79 -> 2910357.8
A35: Bridge reconstruction difference — must be nil | C35: =C34-(C23+C24+C25+C26+C28+C29+C30+C31+C32+C33) -> 0
A37: 4. CAPITAL AND RETURNS
A38: Cumulative sponsor equity | C38: =Returns!$E$54 -> 38639177
A39: Senior debt at exit | C39: ='Transaction & Liquidity'!K$86 -> 5970441.3
A40: Total debt at exit | C40: ='Transaction & Liquidity'!K$86+'Transaction & Liquidity'!K$100 -> 9345441.3
A41: Total debt / consolidated EBITDA | C41: =IF('Operating Case'!K$79=0,0,('Transaction & Liquidity'!K$86+'Transaction & Liquidity'!K$100)/'Operating Case'!K$79) -> 3.2110971
A42: Consolidated coverage ratio | C42: =Controls!$B$74 -> 0.84736747
A43: Exit enterprise value | C43: =Returns!$E$42 -> 27648399
A44: Equity proceeds at exit | C44: =Returns!$E$51 -> 19249990
...

Sheet Base Case Bridge
A1: BASE CASE BRIDGE — FROM ACQUIRED COMPANY ECONOMICS TO PLATFORM ECONOMICS
A2: Every source appears in exactly one category. The tags are display; Controls 62 and 65 reconstruct the same economics from engine primitives.
A4: YEAR-7 BRIDGE — BASE | E4: Origin | F4: Recurrence | G4: Type
A5: Acquired book — contracted EBITDA | C5: ='Operating Case'!K$55 -> 5171512 | E5: ACQUIRED | F5: RECURRING | G5: REVENUE
A6: Organic new business | C6: ='Operating Case'!K$56 -> 1228488 | E6: BUYER-CREATED | F6: RECURRING | G6: REVENUE
A7: Seller payroll removed by centralisation | C7: ='Operating Case'!K$58 -> 8528944.6 | E7: BUYER-CREATED | F7: RECURRING | G7: COST SAVING
A8: Same-scope shared-services replacement | C8: =-'Org & Capacity'!$D$245 -> -3622536.8 | E8: BUYER-CREATED | F8: RECURRING | G8: COST
A9: New-function institutionalisation | C9: =-'Org & Capacity'!$D$247 -> -2547285.7 | E9: BUYER-CREATED | F9: RECURRING | G9: COST
A10: Organic-growth support capacity | C10: =-'Org & Capacity'!$D$249 -> -986816.58 | E10: BUYER-CREATED | F10: RECURRING | G10: COST
A11: Leadership redundancy — uncredited by decision | C11: ='Operating Case'!K$61 -> 0 | E11: BUYER-CREATED | F11: RECURRING | G11: COST SAVING
A12: Transition overlap | C12: ='Operating Case'!K$60 -> -354398.25 | E12: BUYER-CREATED | F12: EPISODIC | G12: COST
A13: Customer-complexity payroll | C13: ='Operating Case'!K$62 -> -967793.57 | E13: BUYER-CREATED | F13: RECURRING | G13: COST
A14: Integration pods | C14: ='Operating Case'!K$64 -> -480000 | E14: BUYER-CREATED | F14: EPISODIC | G14: COST
A15: Other integration savings | C15: ='Operating Case'!K$65 -> 321250 | E15: BUYER-CREATED | F15: RECURRING | G15: COST SAVING
A16: Platform services — Layers 1 to 3, net of delivery | C16: ='Operating Case'!K$67+'Operating Case'!K$68+'Operating Case'!K$69+'Operating Case'!K$70+'Operating Case'!K$71+'Operating Case'!K$72+'Operating Case'!K$63+'Operating Case'!K$73 -> -415602.31 | E16: BUYER-CREATED | F16: RECURRING | G16: REVENUE
A17: HoldCo payroll | C17: ='Operating Case'!K$77 -> -1972440.2 | E17: BUYER-CREATED | F17: RECURRING | G17: COST
A18: HoldCo non-payroll G&A | C18: ='Operating Case'!K$78 -> -992963.38 | E18: BUYER-CREATED | F18: RECURRING | G18: COST
A19: CONSOLIDATED PLATFORM EBITDA — YEAR 7 | C19: ='Operating Case'!K$79 -> 2910357.8
A20: Tagged rows reconstruct the total — must be nil | C20: =C19-SUM(C5:C18) -> 0
A21: Nearshore delivery saving is inside the replacement line above and is never a separate bridge row | C21: ='Org & Capacity'!$D$259 -> 1532367.6
A23: Value creation by category, Year 7
A24: Acquired, recurring | C24: =C5 -> 5171512
A25: Buyer-created revenue | C25: =C6+C16 -> 812885.67
A26: Buyer-created cost savings | C26: =C7+C11+C15 -> 8850194.6
A27: Buyer-created cost | C27: =C8+C9+C10+C13+C17+C18 -> -11089836
A28: Episodic | C28: =C12+C14 -> -834398.25
A29: =" Case shown: Base | "&Assumptions!$E$8&" | "&Assumptions!$E$9 -> Case shown: Base | FULL CASE |
A31: 1. OPERATING SNAPSHOT
A32: Line | D32: Close | E32: Year 1 | F32: Year 2 | G32: Year 3 | H32: Year 4 | I32: Year 5 | J32: Year 6 | K32: Year 7 | L32: Year 8 | M32: Year 9 | N32: Year 10
A33: Managed units | B33: units | C33: [C] | D33: ='Operating Case'!D$50 -> 7343.75 | E33: ='Operating Case'!E$50 -> 10097.656 | F33: ='Operating Case'!F$50 -> 15888.497 | G33: ='Operating Case'!G$50 -> 26492.36 | H33: ='Operating Case'!H$50 -> 37328.004 | I33: ='Operating Case'!I$50 -> 44168.302 | J33: ='Operating Case'!J$50 -> 50000 | K33: ='Operating Case'!K$50 -> 50000 | ... N33: ='Operating Case'!N$50 -> 50000
A34: Properties | B34: props | C34: [C] | D34: ='Operating Case'!D$51 -> 29.375 | E34: ='Operating Case'!E$51 -> 40.390625 | F34: ='Operating Case'!F$51 -> 63.553988 | G34: ='Operating Case'!G$51 -> 105.96944 | H34: ='Operating Case'!H$51 -> 149.31202 | I34: ='Operating Case'!I$51 -> 176.67321 | J34: ='Operating Case'!J$51 -> 200 | K34: ='Operating Case'!K$51 -> 200 | ... N34: ='Operating Case'!N$51 -> 200
A35: Clients | B35: clients | C35: [OQ] | D35: ='Operating Case'!D$52 -> 5.64 | E35: ='Operating Case'!E$52 -> 6.9425714 | F35: ='Operating Case'!F$52 -> 10.412685 | G35: ='Operating Case'!G$52 -> 14.769785 | H35: ='Operating Case'!H$52 -> 20.932123 | I35: ='Operating Case'!I$52 -> 24.875588 | J35: ='Operating Case'!J$52 -> 28.254815 | K35: ='Operating Case'!K$52 -> 28.330667 | ... N35: ='Operating Case'!N$52 -> 28.330667
A36: Equivalent regimes above baseline | B36: regimes | C36: [E] | D36: ='Operating Case'!D$53 -> 0.7625 | E36: ='Operating Case'!E$53 -> 1.1695536 | F36: ='Operating Case'!F$53 -> 2.2539642 | G36: ='Operating Case'!G$53 -> 3.6155579 | H36: ='Operating Case'!H$53 -> 5.5412883 | I36: ='Operating Case'!I$53 -> 6.7736212 | J36: ='Operating Case'!J$53 -> 7.8296296 | K36: ='Operating Case'!K$53 -> 7.8533333 | ... N36: ='Operating Case'!N$53 -> 7.8533333
A37: Recurring revenue | B37: $ | C37: [C] | D37: ='Operating Case'!D$54 -> 4799015.4 | E37: ='Operating Case'!E$54 -> 6598646.1 | F37: ='Operating Case'!F$54 -> 10382862 | G37: ='Operating Case'!G$54 -> 17312306 | H37: ='Operating Case'!H$54 -> 24393214 | I37: ='Operating Case'!I$54 -> 28863232 | J37: ='Operating Case'!J$54 -> 32674147 | K37: ='Operating Case'!K$54 -> 32674147 | ... N37: ='Operating Case'!N$54 -> 32674147
A38: Standalone acquired EBITDA | B38: $ | C38: [C] | D38: ='Operating Case'!D$55 -> 940000 | E38: ='Operating Case'!E$55 -> 1292500 | F38: ='Operating Case'!F$55 -> 1913840 | G38: ='Operating Case'!G$55 -> 3067380.7 | H38: ='Operating Case'!H$55 -> 4170543.9 | I38: ='Operating Case'!I$55 -> 4535738 | J38: ='Operating Case'!J$55 -> 4868429.8 | K38: ='Operating Case'!K$55 -> 5171512 | ... N38: ='Operating Case'!N$55 -> 4228547
A39: Integrated DealCo EBITDA | B39: $ | C39: [C] | D39: ='Operating Case'!D$76 -> -416363.34 | E39: ='Operating Case'!E$76 -> -314237.59 | F39: ='Operating Case'!F$76 -> 619888.55 | G39: ='Operating Case'!G$76 -> 1893784.4 | H39: ='Operating Case'!H$76 -> 3379256.8 | I39: ='Operating Case'!I$76 -> 4732208.3 | J39: ='Operating Case'!J$76 -> 5366817 | K39: ='Operating Case'!K$76 -> 5875761.4 | ... N39: ='Operating Case'!N$76 -> 4979305.6
A40: Consolidated platform EBITDA | B40: $ | C40: [C] | D40: ='Operating Case'!D$79 -> -2562538.6 | E40: ='Operating Case'!E$79 -> -2666125.2 | F40: ='Operating Case'!F$79 -> -1823555.7 | G40: ='Operating Case'!G$79 -> -645223.17 | H40: ='Operating Case'!H$79 -> 740483.36 | I40: ='Operating Case'!I$79 -> 1989260.4 | J40: ='Operating Case'!J$79 -> 2515068.6 | K40: ='Operating Case'!K$79 -> 2910357.8 | ... N40: ='Operating Case'!N$79 -> 1641331.6
A41: PMC-borne corporate FTE | B41: FTE | C41: [C] | D41: ='Operating Case'!D$84 -> 19 | E41: ='Operating Case'!E$84 -> 27.407813 | F41: ='Operating Case'!F$84 -> 31.87108 | G41: ='Operating Case'!G$84 -> 43.719389 | H41: ='Operating Case'!H$84 -> 57.586241 | I41: ='Operating Case'!I$84 -> 63.133465 | J41: ='Operating Case'!J$84 -> 68.6 | K41: ='Operating Case'!K$84 -> 68.6 | ... N41: ='Operating Case'!N$84 -> 68.6
A42: Owner-reimbursed onsite FTE — memo | B42: FTE | C42: [F/C] | D42: ='Org & Capacity'!D$199 -> 178 | E42: ='Org & Capacity'!E$199 -> 244 | F42: ='Org & Capacity'!F$199 -> 382 | G42: ='Org & Capacity'!G$199 -> 633 | H42: ='Org & Capacity'!H$199 -> 894 | I42: ='Org & Capacity'!I$199 -> 1056 | J42: ='Org & Capacity'!J$199 -> 1193 | K42: ='Org & Capacity'!K$199 -> 1193 | ... N42: ='Org & Capacity'!N$199 -> 1193
A43: Recurring capex | B43: $ | C43: [A] | D43: ='Operating Case'!D$81 -> -183593.75 | E43: ='Operating Case'!E$81 -> -252441.41 | F43: ='Operating Case'!F$81 -> -397212.42 | G43: ='Operating Case'!G$81 -> -662309.01 | H43: ='Operating Case'!H$81 -> -933200.1 | I43: ='Operating Case'!I$81 -> -1104207.6 | J43: ='Operating Case'!J$81 -> -1250000 | K43: ='Operating Case'!K$81 -> -1250000 | ... N43: ='Operating Case'!N$81 -> -1250000
...

Sheet Evidence & Market
A1: EVIDENCE AND MARKET
A2: Owner GL, PMA fee architecture, density rules, the named target universe and the compensation source register. Everything downstream reads from here; nothing here reads from anywhere else.
A4: 1. OWNER GENERAL LEDGER — Forum on San Felipe, Jan–Jul 2026, Pinnacle / Cushman & Wakefield
A5: Provided by Galium Capital. Proves what the owner pays. It does not reveal the manager delivery cost, so it evidences gross revenue architecture and willingness to pay, never retained margin.
A6: PMA residential units | C6: 361 | H6: Executed Forum PMA, section 1.2
A7: GL software and service billing units | C7: 368 | H7: $566.72/$1.54 and $570.40/$1.55 both resolve to 368. Open with Galium.
A8: Months in the YTD extract | C8: 7 | H8: January to July 2026, accrual basis
A9: Annualisation factor | C9: =12/C8 -> 1.7142857
A11: Fee category | B11: Classification | C11: Grade | D11: YTD GL | E11: Annualised | F11: $/PMA unit/yr | H11: Note
A12: Core management fee | B12: Core recurring fee | C12: [F] | D12: 107491.87 | E12: =D12*$C$9 -> 184271.78 | F12: =E12/$C$6 -> 510.44814 | H12: Account 4223-000.
A13: Benefits and payroll administration | B13: Inherited retained service | C13: [F] | D13: 7527.29 | E13: =D13*$C$9 -> 12903.926 | F13: =E13/$C$6 -> 35.744947 | H13: Account 4158-000. Three percent of onsite payroll under the PMA.
A14: Revenue-management pricing advisory | B14: Inherited retained service | C14: [F] | D14: 3992.8 | E14: =D14*$C$9 -> 6844.8 | F14: =E14/$C$6 -> 18.960665 | H14: $1.55 per unit per month. Direct overlap with buyer-created Layer 2.
A15: Training and operating platform | B15: Inherited retained service | C15: [F] | D15: 3967.04 | E15: =D15*$C$9 -> 6800.64 | F15: =E15/$C$6 -> 18.838338 | H15: $1.54 per unit per month. Direct overlap with buyer-created Layer 1.
A16: Applications and IT support | B16: Inherited retained service | C16: [F] | D16: 980 | E16: =D16*$C$9 -> 1680 | F16: =E16/$C$6 -> 4.6537396 | H16: $140 per month under the PMA.
A17: IT infrastructure and email licensing | B17: Inherited retained service | C17: [F] | D17: 3755 | E17: =D17 -> 3755 | F17: =E17/$C$6 -> 10.401662 | H17: Annual charge, not annualised.
A18: Yardi licensing | B18: Third-party pass-through | C18: [F] | D18: 11463.2 | E18: =D18*$C$9 -> 19651.2 | F18: =E18/$C$6 -> 54.435457 | H18: $4.45 per unit per month. Software licensing incurred by the manager for the property. Zero retained margin by construction.
A20: 2. EVIDENCED REVENUE ARCHITECTURE — drives Assumptions
A21: Core management fee per unit per year | B21: $/unit | C21: =F12 -> 510.44814 | H21: Replaces the $484 placeholder. Observed.
A22: Inherited retained-service revenue per unit | B22: $/unit | C22: =SUM(F13:F17) -> 88.599351 | H22: Gross billed for services the manager delivers. Upper bound before delivery cost, never margin.
A23: Third-party pass-through per unit | B23: $/unit | C23: =F18 -> 54.435457 | H23: In revenue, never in EBITDA contribution. Zero manager margin.
A24: Episodic project / construction / consulting fees per unit | B24: $/unit | C24: =0 -> 0 | H24: The PMA permits a 5% project-management fee and $135/hour consulting. Absent from this extract. Zero in Base until target history supports it.
A25: Total RECURRING billed to the owner per unit — excludes episodic | B25: $/unit | C25: =C21+C22+C23 -> 653.48294
A26: Platform-like services the incumbent already bills | B26: $/unit | C26: =F14+F15+F16 -> 42.452742 | H26: Revenue management, training and IT support. Buyer-created Layers 1 and 2 displace these rather than adding to them.
A27: RealPage AI revenue-management software | B27: Third-party tooling | C27: =F27 -> 24.042881 | D27: 5063.03 | E27: =D27*$C$9 -> 8679.48 | F27: =E27/$C$6 -> 24.042881 | H27: $24.04 per unit per year. The Layer 2 delivery cost should not sit below this.
A28: Recurring buyer-created service revenue per unit | B28: $/unit | C28: =0 -> 0 | D28: Nil in Base. Exists so that project, construction and other episodic revenue can never enter the recurring base through one combined interface line. Episodic sits at C24 and is reported separately throughout.
A29: 3. PMA FEE ARCHITECTURE — classification from four executed agreements
A30: Reference and classification only. Not a live engine. Future target GL and PMA data overwrite the generic assumptions on the next tab.
A31: Revenue concept | B31: Economic treatment | C31: Evidence | H31: Note
A32: 1. Core management fee | B32: Recurring PMC revenue | C32: [F] | H32: Percentage of collected revenue, subject to property minimums. 2.25%-3.0% across the four PMAs.
A33: 2. Inherited retained recurring services | B33: Recurring PMC revenue, delivery cost unknown | C33: [F] | H33: Benefits administration, revenue management, training, IT support. Evidenced in all four PMAs and now in the Forum GL.
A34: 3. Third-party pass-through and owner reimbursements | B34: Never PMC revenue | C34: [F] | H34: Yardi and RealPage licensing, onsite payroll reimbursement. The platform administers; it does not margin on it.
A35: 4. Episodic project and construction fees | B35: Recurring only if target history supports it | C35: [C] | H35: 5% project-management fee, $135/hour consulting, repair supervision. Zero in Base.
A36: 5. Incentive fees | B36: Zero until contracted and earned | C36: [F] | H36: Dayrise and Greystar both carry incentive structures. No speculative credit.
A37: 6. Buyer-created Layers 1 to 3 | B37: Buyer-created; zeroed by the evidence switch | C37: [A] | H37: Must net inherited overlapping scope. The owner dollar cannot be monetised twice.
A38: Nearshore delivered employment cost index — evidence reference | B38: x | C38: 0.46 | D38: Abacus real-estate engagement: seven-person dedicated team invoiced at $401,264 against $878,020 estimated in Miami, 54% saving, covering accounting manager, FP&A, treasury, staff accountant/AP and compliance. [C] comparable. Not the Base operating assumption; Org & Capacity D25 carries the 0.40x Jack decision, and this index governs the evidence-constrained case.
A39: 4. DENSITY OPERATING RULES
A40: Density drives field supervision, local recruiting and training, client coverage, vendor and compliance coverage and travel. It does NOT drive property accounting, AP/AR/payroll or centralised technology, which are property, entity and transaction driven.
A41: Acquisition class | B41: Units per city | C41: Grade | D41: RPM span | E41: Maint. span | F41: Support x | H41: Use
A42: Infill | B42: Dense. >=500 units per city, ideally >=750 | C42: [E] | D42: 12 | E42: 60 | F42: 0.9 | H42: Inside existing RPM, vendor and shared-services geometry.
A43: Clustered | B43: Base. 350-600 units per city | C43: [E] | D43: 10 | E43: 50 | F43: 1 | H43: Base operating pattern. Several adjacent clusters.
...

Sheet Assumptions
A1: ASSUMPTIONS AND CASES
A2: Three operating cases run simultaneously. The acquisition programme and every at-close target fact are identical across them; only post-close operating outcomes vary.
A3: Blue on yellow is the only thing to edit. Green is linked to the evidence tab or derived. Constraints drive the model; objectives are scored against and drive nothing.
I4: Provenance
A5: CASE CONTROL
A6: Case | B6: Units | C6: Grade | D6: Downside | E6: Base | F6: Upside | H6: Note | I6: ASSUMPTION
A7: Case index | D7: 1 | E7: 2 | F7: 3
A8: EVIDENCE-CONSTRAINED SWITCH (1 = strip unevidenced economics from all three cases) | D8: 0 | E8: =IF($D$8=1,"EVIDENCE-CONSTRAINED","FULL CASE") -> FULL CASE | H8: Zeroes buyer-created organic wins, other integration savings, local payroll elimination, leadership redundancy, all three layers, adoption and implementation. Replacement shared-services cost, HoldCo cost and transition overlap are retained as required operating costs. Inherited contracted revenue and the acquisition programme are unchanged.
A11: HORIZON AND HARD CONSTRAINTS — these drive the model
A12: Target year | B12: year | C12: [D] | D12: 7 | E12: 7 | F12: 7 | I12: JACK DECISION
A13: Exit year | B13: year | C13: [D] | D13: 7 | E13: 7 | F13: 7 | I13: JACK DECISION
A14: Long-hold scenario year | B14: year | C14: [D] | D14: 10 | E14: 10 | F14: 10 | I14: JACK DECISION
A15: Sponsor hurdle IRR | B15: % | C15: [D] | D15: 0.25 | E15: 0.25 | F15: 0.25 | I15: JACK DECISION
A16: Managed-unit ceiling at the target year | B16: units | C16: [D] | D16: 50000 | E16: 50000 | F16: 50000 | H16: Hard planning constraint. Common to all three cases because at-close facts are frozen. | I16: JACK DECISION
A17: Average units per property | B17: units | C17: [D] | D17: 250 | E17: 250 | F17: 250 | H17: Authoritative Base across all cases. The 200 / 225 / 250 work remains a sensitivity on Org & Capacity, not an alternate Base. | I17: JACK DECISION
A18: Implied properties at the ceiling | B18: properties | C18: [C] | D18: =D16/D17 -> 200 | E18: =E16/E17 -> 200 | F18: =F16/F17 -> 200 | H18: Derived, not entered. The managed-unit ceiling divided by units per property. Actual properties at exit are reported downstream and are the arithmetic consequence of units, never a separate assumption. | I18: [C] COMPARABLE
A19: Exit EBITDA basis (1 reported / 2 exit run-rate) | B19: flag | C19: [D] | D19: 1 | E19: 1 | F19: 1 | I19: JACK DECISION
A20: Acquisition closing fraction of year | B20: % | C20: [D] | D20: 0.5 | E20: 0.5 | F20: 0.5 | I20: JACK DECISION
A22: PLANNING OBJECTIVES — the model is scored against these; they drive nothing
A23: Objective — consolidated platform EBITDA after HoldCo | B23: $ | C23: [D] | D23: 10000000 | E23: 10000000 | F23: 10000000 | H23: Design objective, not a driver. The programme is constrained by the unit ceiling and target quality, so the shortfall is a finding and is never engineered away. | I23: JACK DECISION
A24: Objective — clients at the exit year | B24: clients | C24: [D] | D24: 30 | E24: 30 | F24: 30 | H24: Scored against, never used to size anything. Actual clients are derived from clients acquired per deal and retention, and are reported on the Operating Case, Business Plan and IC Summary. | I24: JACK DECISION
A26: DEAL-LEVEL ACQUISITION FACTS — frozen across operating cases
A27: Core management fee per unit per year | B27: $/unit | C27: [C] | D27: ='Evidence & Market'!$C$21 -> 510.44814 | E27: ='Evidence & Market'!$C$21 -> 510.44814 | F27: ='Evidence & Market'!$C$21 -> 510.44814 | H27: Forum GL. [F] on the evidence tab; applied to unidentified targets it is a comparable. | I27: [C]
A28: Inherited retained-service revenue per unit | B28: $/unit | C28: [C] | D28: ='Evidence & Market'!$C$22 -> 88.599351 | E28: ='Evidence & Market'!$C$22 -> 88.599351 | F28: ='Evidence & Market'!$C$22 -> 88.599351 | I28: [C]
A29: Third-party pass-through per unit | B29: $/unit | C29: [C] | D29: ='Evidence & Market'!$C$23 -> 54.435457 | E29: ='Evidence & Market'!$C$23 -> 54.435457 | F29: ='Evidence & Market'!$C$23 -> 54.435457 | H29: In revenue, never in EBITDA contribution. | I29: [C]
A30: Episodic project and consulting fees per unit | B30: $/unit | C30: [C] | D30: ='Evidence & Market'!$C$24 -> 0 | E30: ='Evidence & Market'!$C$24 -> 0 | F30: ='Evidence & Market'!$C$24 -> 0 | H30: Zero in Base until target history supports it. | I30: [C]
A31: ORG-20 Target payroll structure — payroll share of operating cost | B31: % | C31: [OQ] | D31: =$E$31 -> 0.75 | E31: 0.75 | F31: =$E$31 -> 0.75 | H31: PRINCIPAL DECISION, 4 Sep 2026, set at 75%. Replaces the former non-payroll share of revenue. Target compensation is solved to this share of the acquired cost base rather than assumed from platform benchmarks. Total payroll share alone does not determine centralisation value: the dollars must sit in the roles the platform can actually eliminate. Resolving it requires a P&L and trial balance, a payroll register, an employee census by role and title with loaded employer cost, outsourced finance, legal and compliance spend, benefit and payroll-tax costs, and intercompany allocations — prioritising a 6,000-unit target because that is the repeated tuck-in archetype. Frozen across operating cases; applies to acquired targets only, never to HoldCo or shared services, which carry full platform rates. | I31: JACK DECISION
A32: Target normalized EBITDA per managed unit at close | B32: $/unit | C32: [OQ] | D32: =E32 -> 128 | E32: 128 | F32: =E32 -> 128 | H32: PRIMARY INPUT. With units per property and the evidenced revenue per unit, this is the only target-quality assumption in the model. Units, properties and the EBITDA margin are all derived from it. Set to the acquisition-quality screen: the minimum EBITDA per unit at which the instructed cadence, EBITDA sizes and 50,000-unit ceiling coexist. A screening criterion requiring target GL evidence, never an observed fact. | I32: OPEN QUESTION
A33: Implied target normalized EBITDA margin | B33: % | C33: [C] | D33: =D32/(D27+D28+D29+D30) -> 0.19587351 | E33: =E32/(E27+E28+E29+E30) -> 0.19587351 | F33: =F32/(F27+F28+F29+F30) -> 0.19587351 | H33: Set to the acquisition-quality screen derived on Operating Case: the minimum normalized margin at which the instructed cadence, EBITDA sizes and 50,000-unit ceiling coexist. It is a screening criterion for the target universe requiring target GL evidence, never an observed fact. One common at-close acquisition assumption. The same company is purchased in every case, so Downside and Upside read the Base cell by formula and cannot diverge. Acquisition quality is tested in the sensitivity block on Returns, never inside an operating scenario. | I33: [C] COMPARABLE
A34: Anchor acquired EBITDA | B34: $ | C34: [D] | D34: 1000000 | E34: 1000000 | F34: 1000000 | H34: Instructed minimum. Live on the EBITDA-led basis. | I34: JACK DECISION
A35: Acquired EBITDA — large tuck-in | B35: $ | C35: [D] | D35: 750000 | E35: 750000 | F35: 750000 | H35: One per year, as instructed. | I35: JACK DECISION
A36: Acquired EBITDA — small tuck-in | B36: $ | C36: [D] | D36: 500000 | E36: 500000 | F36: 500000 | H36: Filler size. Available but not used in the live Base programme because the unit ceiling leaves no room; the schedule reports this explicitly. | I36: JACK DECISION
A37: Acquired EBITDA — mid-market addition | B37: $ | C37: [D] | D37: 1250000 | E37: 1250000 | F37: 1250000 | H37: Year 3 only. At or above the $800k pricing threshold, so it prices off the larger-target convention at 6.0x. | I37: JACK DECISION
A38: Entry-multiple band threshold — acquired EBITDA | B38: $ | C38: [D] | D38: 800000 | E38: 800000 | F38: 800000 | H38: A target BELOW this EBITDA prices off the smaller-target convention; at or above it, off the larger-target convention. Applied automatically by deal size. No deal in the live programme sits on the boundary, so the convention carries no knife-edge risk. | I38: JACK DECISION
A39: Anchor entry multiple | B39: x | C39: [D] | D39: 6 | E39: 6 | F39: 6 | H39: The anchor is priced explicitly and does not use the band. | I39: JACK DECISION
A40: Entry multiple — targets below the threshold | B40: x | C40: [D] | D40: 4 | E40: 4 | F40: 4 | H40: Principal decision. The banker indication for smaller businesses was approximately 3-4x; 4.0x sits at the top of that range. The sensitivity band below is applied on Returns, never as an operating scenario. | I40: JACK DECISION
A41: Pricing sensitivity band — below the threshold | B41: x | C41: [A] | D41: 4.5 | E41: 4 | F41: 3.5 | H41: High 4.5x / Base 4.0x / Low 3.5x, applied on Returns as a purchase-price sensitivity. Graded [A]: the 4.5x high case sits above the 3-4x banker indication for smaller businesses and is not supported by it. | I41: ASSUMPTION
A42: Entry multiple — targets at or above the threshold | B42: x | C42: [D] | D42: 6 | E42: 6 | F42: 6 | H42: Principal decision. Larger targets are competitively priced and do not clear at 3-4x. | I42: JACK DECISION
A43: Clients acquired with the anchor | B43: clients | C43: [OQ] | D43: 6 | E43: 6 | F43: 6 | I43: OPEN QUESTION
A44: Clients acquired per tuck-in | B44: clients | C44: [OQ] | D44: 3.4 | E44: 3.4 | F44: 3.4 | H44: Set so retained clients land near the 30 instruction at Year 7 after change-of-control loss and ordinary churn. | I44: OPEN QUESTION
...

Sheet Acquisition Schedule
A1: ACQUISITION SCHEDULE — ONE ROW PER DEAL
A2: Every field is an at-close fact and is identical in Downside, Base and Upside. Operating cases change what happens after close, never the company that was bought.
A5: Deal ID | B5: Target / type | C5: Market | D5: Class | E5: Close yr | F5: Acq EBITDA | G5: Revenue* | H5: Margin* | I5: Units* | J5: Props* | K5: Clients* | L5: Regimes | M5: Entry x | N5: EV | O5: Senior | P5: Seller note | Q5: Integr. cost | R5: Txn cost | S5: Ldrs acq | T5: Retained | U5: Redundant | V5: Density x | W5: Units x dens
A6: ANCHOR | B6: Backbone platform | C6: Dallas | D6: Clustered | E6: 0 | F6: =INDEX(Assumptions!$D$34:$F$34,1,2) -> 1000000 | G6: =I6*(INDEX(Assumptions!$D$27:$F$27,1,2)+INDEX(Assumptions!$D$28:$F$28,1,2)+INDEX(Assumptions!$D$29:$F$29,1,2)+INDEX(Assumptions!$D$30:$F$30,1,2)) -> 5105335.5 | H6: =IF(G6=0,0,F6/G6) -> 0.19587351 | I6: =F6/INDEX(Assumptions!$D$32:$F$32,1,2) -> 7812.5 | J6: =I6/INDEX(Assumptions!$D$17:$F$17,1,2) -> 31.25 | K6: =INDEX(Assumptions!$D$43:$F$43,1,2) -> 6 | L6: =K6*INDEX(Assumptions!$D$46:$F$46,1,2)/10 -> 1.5 | M6: =INDEX(Assumptions!$D$39:$F$39,1,2) -> 6 | N6: =F6*M6 -> 6000000 | O6: =N6*INDEX(Assumptions!$D$95:$F$95,1,2) -> 2100000 | P6: =N6*INDEX(Assumptions!$D$98:$F$98,1,2) -> 900000 | Q6: =INDEX(Assumptions!$D$63:$F$63,1,2) -> 175000 | R6: =INDEX(Assumptions!$D$64:$F$64,1,2)+N6*INDEX(Assumptions!$D$65:$F$65,1,2) -> 255000 | S6: 2 | T6: 1 | U6: =MAX(0,S6-T6) -> 1 | V6: =INDEX('Evidence & Market'!$F$42:$F$44,MATCH($D6,'Evidence & Market'!$A$42:$A$44,0)) -> 1 | W6: =I6*V6 -> 7812.5
A7: TK01 | B7: Large tuck-in | C7: Dallas | D7: Infill | E7: 1 | F7: =INDEX(Assumptions!$D$35:$F$35,1,2) -> 750000 | G7: =I7*(INDEX(Assumptions!$D$27:$F$27,1,2)+INDEX(Assumptions!$D$28:$F$28,1,2)+INDEX(Assumptions!$D$29:$F$29,1,2)+INDEX(Assumptions!$D$30:$F$30,1,2)) -> 3829001.6 | H7: =IF(G7=0,0,F7/G7) -> 0.19587351 | I7: =F7/INDEX(Assumptions!$D$32:$F$32,1,2) -> 5859.375 | J7: =I7/INDEX(Assumptions!$D$17:$F$17,1,2) -> 23.4375 | K7: =INDEX(Assumptions!$D$44:$F$44,1,2) -> 3.4 | L7: =K7*INDEX(Assumptions!$D$46:$F$46,1,2)/10 -> 0.85 | M7: =IF(F7<INDEX(Assumptions!$D$38:$F$38,1,2),INDEX(Assumptions!$D$40:$F$40,1,2),INDEX(Assumptions!$D$42:$F$42,1,2)) -> 4 | N7: =F7*M7 -> 3000000 | O7: =N7*INDEX(Assumptions!$D$95:$F$95,1,2) -> 1050000 | P7: =N7*INDEX(Assumptions!$D$98:$F$98,1,2) -> 450000 | Q7: =INDEX(Assumptions!$D$63:$F$63,1,2) -> 175000 | R7: =INDEX(Assumptions!$D$64:$F$64,1,2)+N7*INDEX(Assumptions!$D$65:$F$65,1,2) -> 165000 | S7: 1 | T7: 1 | U7: =MAX(0,S7-T7) -> 0 | V7: =INDEX('Evidence & Market'!$F$42:$F$44,MATCH($D7,'Evidence & Market'!$A$42:$A$44,0)) -> 0.9 | W7: =I7*V7 -> 5273.4375
A8: TK02 | B8: Large tuck-in | C8: Dallas | D8: Infill | E8: 2 | F8: =INDEX(Assumptions!$D$35:$F$35,1,2) -> 750000 | G8: =I8*(INDEX(Assumptions!$D$27:$F$27,1,2)+INDEX(Assumptions!$D$28:$F$28,1,2)+INDEX(Assumptions!$D$29:$F$29,1,2)+INDEX(Assumptions!$D$30:$F$30,1,2)) -> 3829001.6 | H8: =IF(G8=0,0,F8/G8) -> 0.19587351 | I8: =F8/INDEX(Assumptions!$D$32:$F$32,1,2) -> 5859.375 | J8: =I8/INDEX(Assumptions!$D$17:$F$17,1,2) -> 23.4375 | K8: =INDEX(Assumptions!$D$44:$F$44,1,2) -> 3.4 | L8: =K8*INDEX(Assumptions!$D$46:$F$46,1,2)/10 -> 0.85 | M8: =IF(F8<INDEX(Assumptions!$D$38:$F$38,1,2),INDEX(Assumptions!$D$40:$F$40,1,2),INDEX(Assumptions!$D$42:$F$42,1,2)) -> 4 | N8: =F8*M8 -> 3000000 | O8: =N8*INDEX(Assumptions!$D$95:$F$95,1,2) -> 1050000 | P8: =N8*INDEX(Assumptions!$D$98:$F$98,1,2) -> 450000 | Q8: =INDEX(Assumptions!$D$63:$F$63,1,2) -> 175000 | R8: =INDEX(Assumptions!$D$64:$F$64,1,2)+N8*INDEX(Assumptions!$D$65:$F$65,1,2) -> 165000 | S8: 1 | T8: 1 | U8: =MAX(0,S8-T8) -> 0 | V8: =INDEX('Evidence & Market'!$F$42:$F$44,MATCH($D8,'Evidence & Market'!$A$42:$A$44,0)) -> 0.9 | W8: =I8*V8 -> 5273.4375
A9: TK03 | B9: Large tuck-in | C9: Dallas | D9: Clustered | E9: 3 | F9: =INDEX(Assumptions!$D$35:$F$35,1,2) -> 750000 | G9: =I9*(INDEX(Assumptions!$D$27:$F$27,1,2)+INDEX(Assumptions!$D$28:$F$28,1,2)+INDEX(Assumptions!$D$29:$F$29,1,2)+INDEX(Assumptions!$D$30:$F$30,1,2)) -> 3829001.6 | H9: =IF(G9=0,0,F9/G9) -> 0.19587351 | I9: =F9/INDEX(Assumptions!$D$32:$F$32,1,2) -> 5859.375 | J9: =I9/INDEX(Assumptions!$D$17:$F$17,1,2) -> 23.4375 | K9: =INDEX(Assumptions!$D$44:$F$44,1,2) -> 3.4 | L9: =K9*INDEX(Assumptions!$D$46:$F$46,1,2)/10 -> 0.85 | M9: =IF(F9<INDEX(Assumptions!$D$38:$F$38,1,2),INDEX(Assumptions!$D$40:$F$40,1,2),INDEX(Assumptions!$D$42:$F$42,1,2)) -> 4 | N9: =F9*M9 -> 3000000 | O9: =N9*INDEX(Assumptions!$D$95:$F$95,1,2) -> 1050000 | P9: =N9*INDEX(Assumptions!$D$98:$F$98,1,2) -> 450000 | Q9: =INDEX(Assumptions!$D$63:$F$63,1,2) -> 175000 | R9: =INDEX(Assumptions!$D$64:$F$64,1,2)+N9*INDEX(Assumptions!$D$65:$F$65,1,2) -> 165000 | S9: 1 | T9: 1 | U9: =MAX(0,S9-T9) -> 0 | V9: =INDEX('Evidence & Market'!$F$42:$F$44,MATCH($D9,'Evidence & Market'!$A$42:$A$44,0)) -> 1 | W9: =I9*V9 -> 5859.375
A10: TK04 | B10: Mid-market addition | C10: Columbus | D10: Extension | E10: 3 | F10: =INDEX(Assumptions!$D$37:$F$37,1,2) -> 1250000 | G10: =I10*(INDEX(Assumptions!$D$27:$F$27,1,2)+INDEX(Assumptions!$D$28:$F$28,1,2)+INDEX(Assumptions!$D$29:$F$29,1,2)+INDEX(Assumptions!$D$30:$F$30,1,2)) -> 6381669.4 | H10: =IF(G10=0,0,F10/G10) -> 0.19587351 | I10: =F10/INDEX(Assumptions!$D$32:$F$32,1,2) -> 9765.625 | J10: =I10/INDEX(Assumptions!$D$17:$F$17,1,2) -> 39.0625 | K10: =INDEX(Assumptions!$D$44:$F$44,1,2) -> 3.4 | L10: =K10*INDEX(Assumptions!$D$46:$F$46,1,2)/10 -> 0.85 | M10: =IF(F10<INDEX(Assumptions!$D$38:$F$38,1,2),INDEX(Assumptions!$D$40:$F$40,1,2),INDEX(Assumptions!$D$42:$F$42,1,2)) -> 6 | N10: =F10*M10 -> 7500000 | O10: =N10*INDEX(Assumptions!$D$95:$F$95,1,2) -> 2625000 | P10: =N10*INDEX(Assumptions!$D$98:$F$98,1,2) -> 1125000 | Q10: =INDEX(Assumptions!$D$63:$F$63,1,2) -> 175000 | R10: =INDEX(Assumptions!$D$64:$F$64,1,2)+N10*INDEX(Assumptions!$D$65:$F$65,1,2) -> 300000 | S10: 2 | T10: 1 | U10: =MAX(0,S10-T10) -> 1 | V10: =INDEX('Evidence & Market'!$F$42:$F$44,MATCH($D10,'Evidence & Market'!$A$42:$A$44,0)) -> 1.15 | W10: =I10*V10 -> 11230.469
A11: TK05 | B11: Large tuck-in | C11: Dallas | D11: Infill | E11: 4 | F11: =INDEX(Assumptions!$D$35:$F$35,1,2) -> 750000 | G11: =I11*(INDEX(Assumptions!$D$27:$F$27,1,2)+INDEX(Assumptions!$D$28:$F$28,1,2)+INDEX(Assumptions!$D$29:$F$29,1,2)+INDEX(Assumptions!$D$30:$F$30,1,2)) -> 3829001.6 | H11: =IF(G11=0,0,F11/G11) -> 0.19587351 | I11: =F11/INDEX(Assumptions!$D$32:$F$32,1,2) -> 5859.375 | J11: =I11/INDEX(Assumptions!$D$17:$F$17,1,2) -> 23.4375 | K11: =INDEX(Assumptions!$D$44:$F$44,1,2) -> 3.4 | L11: =K11*INDEX(Assumptions!$D$46:$F$46,1,2)/10 -> 0.85 | M11: =IF(F11<INDEX(Assumptions!$D$38:$F$38,1,2),INDEX(Assumptions!$D$40:$F$40,1,2),INDEX(Assumptions!$D$42:$F$42,1,2)) -> 4 | N11: =F11*M11 -> 3000000 | O11: =N11*INDEX(Assumptions!$D$95:$F$95,1,2) -> 1050000 | P11: =N11*INDEX(Assumptions!$D$98:$F$98,1,2) -> 450000 | Q11: =INDEX(Assumptions!$D$63:$F$63,1,2) -> 175000 | R11: =INDEX(Assumptions!$D$64:$F$64,1,2)+N11*INDEX(Assumptions!$D$65:$F$65,1,2) -> 165000 | S11: 1 | T11: 1 | U11: =MAX(0,S11-T11) -> 0 | V11: =INDEX('Evidence & Market'!$F$42:$F$44,MATCH($D11,'Evidence & Market'!$A$42:$A$44,0)) -> 0.9 | W11: =I11*V11 -> 5273.4375
A12: TK06 | B12: Large tuck-in | C12: Columbus | D12: Clustered | E12: 5 | F12: =INDEX(Assumptions!$D$35:$F$35,1,2) -> 750000 | G12: =I12*(INDEX(Assumptions!$D$27:$F$27,1,2)+INDEX(Assumptions!$D$28:$F$28,1,2)+INDEX(Assumptions!$D$29:$F$29,1,2)+INDEX(Assumptions!$D$30:$F$30,1,2)) -> 3829001.6 | H12: =IF(G12=0,0,F12/G12) -> 0.19587351 | I12: =F12/INDEX(Assumptions!$D$32:$F$32,1,2) -> 5859.375 | J12: =I12/INDEX(Assumptions!$D$17:$F$17,1,2) -> 23.4375 | K12: =INDEX(Assumptions!$D$44:$F$44,1,2) -> 3.4 | L12: =K12*INDEX(Assumptions!$D$46:$F$46,1,2)/10 -> 0.85 | M12: =IF(F12<INDEX(Assumptions!$D$38:$F$38,1,2),INDEX(Assumptions!$D$40:$F$40,1,2),INDEX(Assumptions!$D$42:$F$42,1,2)) -> 4 | N12: =F12*M12 -> 3000000 | O12: =N12*INDEX(Assumptions!$D$95:$F$95,1,2) -> 1050000 | P12: =N12*INDEX(Assumptions!$D$98:$F$98,1,2) -> 450000 | Q12: =INDEX(Assumptions!$D$63:$F$63,1,2) -> 175000 | R12: =INDEX(Assumptions!$D$64:$F$64,1,2)+N12*INDEX(Assumptions!$D$65:$F$65,1,2) -> 165000 | S12: 1 | T12: 1 | U12: =MAX(0,S12-T12) -> 0 | V12: =INDEX('Evidence & Market'!$F$42:$F$44,MATCH($D12,'Evidence & Market'!$A$42:$A$44,0)) -> 1 | W12: =I12*V12 -> 5859.375
A13: TK07 | B13: Large tuck-in | C13: Columbus | D13: Infill | E13: 6 | F13: =INDEX(Assumptions!$D$35:$F$35,1,2) -> 750000 | G13: =I13*(INDEX(Assumptions!$D$27:$F$27,1,2)+INDEX(Assumptions!$D$28:$F$28,1,2)+INDEX(Assumptions!$D$29:$F$29,1,2)+INDEX(Assumptions!$D$30:$F$30,1,2)) -> 3829001.6 | H13: =IF(G13=0,0,F13/G13) -> 0.19587351 | I13: =F13/INDEX(Assumptions!$D$32:$F$32,1,2) -> 5859.375 | J13: =I13/INDEX(Assumptions!$D$17:$F$17,1,2) -> 23.4375 | K13: =INDEX(Assumptions!$D$44:$F$44,1,2) -> 3.4 | L13: =K13*INDEX(Assumptions!$D$46:$F$46,1,2)/10 -> 0.85 | M13: =IF(F13<INDEX(Assumptions!$D$38:$F$38,1,2),INDEX(Assumptions!$D$40:$F$40,1,2),INDEX(Assumptions!$D$42:$F$42,1,2)) -> 4 | N13: =F13*M13 -> 3000000 | O13: =N13*INDEX(Assumptions!$D$95:$F$95,1,2) -> 1050000 | P13: =N13*INDEX(Assumptions!$D$98:$F$98,1,2) -> 450000 | Q13: =INDEX(Assumptions!$D$63:$F$63,1,2) -> 175000 | R13: =INDEX(Assumptions!$D$64:$F$64,1,2)+N13*INDEX(Assumptions!$D$65:$F$65,1,2) -> 165000 | S13: 1 | T13: 1 | U13: =MAX(0,S13-T13) -> 0 | V13: =INDEX('Evidence & Market'!$F$42:$F$44,MATCH($D13,'Evidence & Market'!$A$42:$A$44,0)) -> 0.9 | W13: =I13*V13 -> 5273.4375
A14: TK08 | B14: Large tuck-in | C14: Columbus | D14: Infill | E14: 7 | F14: =INDEX(Assumptions!$D$35:$F$35,1,2) -> 750000 | G14: =I14*(INDEX(Assumptions!$D$27:$F$27,1,2)+INDEX(Assumptions!$D$28:$F$28,1,2)+INDEX(Assumptions!$D$29:$F$29,1,2)+INDEX(Assumptions!$D$30:$F$30,1,2)) -> 3829001.6 | H14: =IF(G14=0,0,F14/G14) -> 0.19587351 | I14: =F14/INDEX(Assumptions!$D$32:$F$32,1,2) -> 5859.375 | J14: =I14/INDEX(Assumptions!$D$17:$F$17,1,2) -> 23.4375 | K14: =INDEX(Assumptions!$D$44:$F$44,1,2) -> 3.4 | L14: =K14*INDEX(Assumptions!$D$46:$F$46,1,2)/10 -> 0.85 | M14: =IF(F14<INDEX(Assumptions!$D$38:$F$38,1,2),INDEX(Assumptions!$D$40:$F$40,1,2),INDEX(Assumptions!$D$42:$F$42,1,2)) -> 4 | N14: =F14*M14 -> 3000000 | O14: =N14*INDEX(Assumptions!$D$95:$F$95,1,2) -> 1050000 | P14: =N14*INDEX(Assumptions!$D$98:$F$98,1,2) -> 450000 | Q14: =INDEX(Assumptions!$D$63:$F$63,1,2) -> 175000 | R14: =INDEX(Assumptions!$D$64:$F$64,1,2)+N14*INDEX(Assumptions!$D$65:$F$65,1,2) -> 165000 | S14: 1 | T14: 1 | U14: =MAX(0,S14-T14) -> 0 | V14: =INDEX('Evidence & Market'!$F$42:$F$44,MATCH($D14,'Evidence & Market'!$A$42:$A$44,0)) -> 0.9 | W14: =I14*V14 -> 5273.4375
A15: TOTAL | F15: =SUM(F6:F14) -> 7500000 | G15: =SUM(G6:G14) -> 38290016 | I15: =SUM(I6:I14) -> 58593.75 | J15: =SUM(J6:J14) -> 234.375 | K15: =SUM(K6:K14) -> 33.2 | N15: =SUM(N6:N14) -> 34500000 | O15: =SUM(O6:O14) -> 12075000 | P15: =SUM(P6:P14) -> 5175000 | Q15: =SUM(Q6:Q14) -> 1575000 | R15: =SUM(R6:R14) -> 1710000 | S15: =SUM(S6:S14) -> 11 | T15: =SUM(T6:T14) -> 9 | U15: =SUM(U6:U14) -> 2
A17: PROGRAMME BY YEAR
A18: Line | F18: Close | G18: Y1 | H18: Y2 | I18: Y3 | J18: Y4 | K18: Y5 | L18: Y6 | M18: Y7 | N18: Y8 | O18: Y9 | P18: Y10
A19: Deals closed | B19: deals | C19: [D] | F19: =COUNTIFS($E$6:$E$14,0) -> 1 | G19: =COUNTIFS($E$6:$E$14,1) -> 1 | H19: =COUNTIFS($E$6:$E$14,2) -> 1 | I19: =COUNTIFS($E$6:$E$14,3) -> 2 | J19: =COUNTIFS($E$6:$E$14,4) -> 1 | K19: =COUNTIFS($E$6:$E$14,5) -> 1 | L19: =COUNTIFS($E$6:$E$14,6) -> 1 | M19: =COUNTIFS($E$6:$E$14,7) -> 1 | N19: =COUNTIFS($E$6:$E$14,8) -> 0 | O19: =COUNTIFS($E$6:$E$14,9) -> 0 | P19: =COUNTIFS($E$6:$E$14,10) -> 0
A20: Acquired EBITDA at acquisition | B20: $ | C20: [OQ] | F20: =SUMIFS($F$6:$F$14,$E$6:$E$14,0) -> 1000000 | G20: =SUMIFS($F$6:$F$14,$E$6:$E$14,1) -> 750000 | H20: =SUMIFS($F$6:$F$14,$E$6:$E$14,2) -> 750000 | I20: =SUMIFS($F$6:$F$14,$E$6:$E$14,3) -> 2000000 | J20: =SUMIFS($F$6:$F$14,$E$6:$E$14,4) -> 750000 | K20: =SUMIFS($F$6:$F$14,$E$6:$E$14,5) -> 750000 | L20: =SUMIFS($F$6:$F$14,$E$6:$E$14,6) -> 750000 | M20: =SUMIFS($F$6:$F$14,$E$6:$E$14,7) -> 750000 | N20: =SUMIFS($F$6:$F$14,$E$6:$E$14,8) -> 0 | O20: =SUMIFS($F$6:$F$14,$E$6:$E$14,9) -> 0 | P20: =SUMIFS($F$6:$F$14,$E$6:$E$14,10) -> 0
A21: Acquired recurring revenue | B21: $ | C21: [C] | F21: =SUMIFS($G$6:$G$14,$E$6:$E$14,0) -> 5105335.5 | G21: =SUMIFS($G$6:$G$14,$E$6:$E$14,1) -> 3829001.6 | H21: =SUMIFS($G$6:$G$14,$E$6:$E$14,2) -> 3829001.6 | I21: =SUMIFS($G$6:$G$14,$E$6:$E$14,3) -> 10210671 | J21: =SUMIFS($G$6:$G$14,$E$6:$E$14,4) -> 3829001.6 | K21: =SUMIFS($G$6:$G$14,$E$6:$E$14,5) -> 3829001.6 | L21: =SUMIFS($G$6:$G$14,$E$6:$E$14,6) -> 3829001.6 | M21: =SUMIFS($G$6:$G$14,$E$6:$E$14,7) -> 3829001.6 | N21: =SUMIFS($G$6:$G$14,$E$6:$E$14,8) -> 0 | O21: =SUMIFS($G$6:$G$14,$E$6:$E$14,9) -> 0 | P21: =SUMIFS($G$6:$G$14,$E$6:$E$14,10) -> 0
A22: Units acquired | B22: units | C22: [C] | F22: =SUMIFS($I$6:$I$14,$E$6:$E$14,0) -> 7812.5 | G22: =SUMIFS($I$6:$I$14,$E$6:$E$14,1) -> 5859.375 | H22: =SUMIFS($I$6:$I$14,$E$6:$E$14,2) -> 5859.375 | I22: =SUMIFS($I$6:$I$14,$E$6:$E$14,3) -> 15625 | J22: =SUMIFS($I$6:$I$14,$E$6:$E$14,4) -> 5859.375 | K22: =SUMIFS($I$6:$I$14,$E$6:$E$14,5) -> 5859.375 | L22: =SUMIFS($I$6:$I$14,$E$6:$E$14,6) -> 5859.375 | M22: =SUMIFS($I$6:$I$14,$E$6:$E$14,7) -> 5859.375 | N22: =SUMIFS($I$6:$I$14,$E$6:$E$14,8) -> 0 | O22: =SUMIFS($I$6:$I$14,$E$6:$E$14,9) -> 0 | P22: =SUMIFS($I$6:$I$14,$E$6:$E$14,10) -> 0
A23: Properties acquired | B23: props | C23: [C] | F23: =SUMIFS($J$6:$J$14,$E$6:$E$14,0) -> 31.25 | G23: =SUMIFS($J$6:$J$14,$E$6:$E$14,1) -> 23.4375 | H23: =SUMIFS($J$6:$J$14,$E$6:$E$14,2) -> 23.4375 | I23: =SUMIFS($J$6:$J$14,$E$6:$E$14,3) -> 62.5 | J23: =SUMIFS($J$6:$J$14,$E$6:$E$14,4) -> 23.4375 | K23: =SUMIFS($J$6:$J$14,$E$6:$E$14,5) -> 23.4375 | L23: =SUMIFS($J$6:$J$14,$E$6:$E$14,6) -> 23.4375 | M23: =SUMIFS($J$6:$J$14,$E$6:$E$14,7) -> 23.4375 | N23: =SUMIFS($J$6:$J$14,$E$6:$E$14,8) -> 0 | O23: =SUMIFS($J$6:$J$14,$E$6:$E$14,9) -> 0 | P23: =SUMIFS($J$6:$J$14,$E$6:$E$14,10) -> 0
A24: Clients acquired | B24: clients | C24: [OQ] | F24: =SUMIFS($K$6:$K$14,$E$6:$E$14,0) -> 6 | G24: =SUMIFS($K$6:$K$14,$E$6:$E$14,1) -> 3.4 | H24: =SUMIFS($K$6:$K$14,$E$6:$E$14,2) -> 3.4 | I24: =SUMIFS($K$6:$K$14,$E$6:$E$14,3) -> 6.8 | J24: =SUMIFS($K$6:$K$14,$E$6:$E$14,4) -> 3.4 | K24: =SUMIFS($K$6:$K$14,$E$6:$E$14,5) -> 3.4 | L24: =SUMIFS($K$6:$K$14,$E$6:$E$14,6) -> 3.4 | M24: =SUMIFS($K$6:$K$14,$E$6:$E$14,7) -> 3.4 | N24: =SUMIFS($K$6:$K$14,$E$6:$E$14,8) -> 0 | O24: =SUMIFS($K$6:$K$14,$E$6:$E$14,9) -> 0 | P24: =SUMIFS($K$6:$K$14,$E$6:$E$14,10) -> 0
A25: Regimes acquired | B25: regimes | C25: [E] | F25: =SUMIFS($L$6:$L$14,$E$6:$E$14,0) -> 1.5 | G25: =SUMIFS($L$6:$L$14,$E$6:$E$14,1) -> 0.85 | H25: =SUMIFS($L$6:$L$14,$E$6:$E$14,2) -> 0.85 | I25: =SUMIFS($L$6:$L$14,$E$6:$E$14,3) -> 1.7 | J25: =SUMIFS($L$6:$L$14,$E$6:$E$14,4) -> 0.85 | K25: =SUMIFS($L$6:$L$14,$E$6:$E$14,5) -> 0.85 | L25: =SUMIFS($L$6:$L$14,$E$6:$E$14,6) -> 0.85 | M25: =SUMIFS($L$6:$L$14,$E$6:$E$14,7) -> 0.85 | N25: =SUMIFS($L$6:$L$14,$E$6:$E$14,8) -> 0 | O25: =SUMIFS($L$6:$L$14,$E$6:$E$14,9) -> 0 | P25: =SUMIFS($L$6:$L$14,$E$6:$E$14,10) -> 0
A26: Acquisition enterprise value | B26: $ | C26: [C] | F26: =SUMIFS($N$6:$N$14,$E$6:$E$14,0) -> 6000000 | G26: =SUMIFS($N$6:$N$14,$E$6:$E$14,1) -> 3000000 | H26: =SUMIFS($N$6:$N$14,$E$6:$E$14,2) -> 3000000 | I26: =SUMIFS($N$6:$N$14,$E$6:$E$14,3) -> 10500000 | J26: =SUMIFS($N$6:$N$14,$E$6:$E$14,4) -> 3000000 | K26: =SUMIFS($N$6:$N$14,$E$6:$E$14,5) -> 3000000 | L26: =SUMIFS($N$6:$N$14,$E$6:$E$14,6) -> 3000000 | M26: =SUMIFS($N$6:$N$14,$E$6:$E$14,7) -> 3000000 | N26: =SUMIFS($N$6:$N$14,$E$6:$E$14,8) -> 0 | O26: =SUMIFS($N$6:$N$14,$E$6:$E$14,9) -> 0 | P26: =SUMIFS($N$6:$N$14,$E$6:$E$14,10) -> 0
A27: Senior debt target | B27: $ | C27: [C] | F27: =SUMIFS($O$6:$O$14,$E$6:$E$14,0) -> 2100000 | G27: =SUMIFS($O$6:$O$14,$E$6:$E$14,1) -> 1050000 | H27: =SUMIFS($O$6:$O$14,$E$6:$E$14,2) -> 1050000 | I27: =SUMIFS($O$6:$O$14,$E$6:$E$14,3) -> 3675000 | J27: =SUMIFS($O$6:$O$14,$E$6:$E$14,4) -> 1050000 | K27: =SUMIFS($O$6:$O$14,$E$6:$E$14,5) -> 1050000 | L27: =SUMIFS($O$6:$O$14,$E$6:$E$14,6) -> 1050000 | M27: =SUMIFS($O$6:$O$14,$E$6:$E$14,7) -> 1050000 | N27: =SUMIFS($O$6:$O$14,$E$6:$E$14,8) -> 0 | O27: =SUMIFS($O$6:$O$14,$E$6:$E$14,9) -> 0 | P27: =SUMIFS($O$6:$O$14,$E$6:$E$14,10) -> 0
A28: Seller notes issued | B28: $ | C28: [C] | F28: =SUMIFS($P$6:$P$14,$E$6:$E$14,0) -> 900000 | G28: =SUMIFS($P$6:$P$14,$E$6:$E$14,1) -> 450000 | H28: =SUMIFS($P$6:$P$14,$E$6:$E$14,2) -> 450000 | I28: =SUMIFS($P$6:$P$14,$E$6:$E$14,3) -> 1575000 | J28: =SUMIFS($P$6:$P$14,$E$6:$E$14,4) -> 450000 | K28: =SUMIFS($P$6:$P$14,$E$6:$E$14,5) -> 450000 | L28: =SUMIFS($P$6:$P$14,$E$6:$E$14,6) -> 450000 | M28: =SUMIFS($P$6:$P$14,$E$6:$E$14,7) -> 450000 | N28: =SUMIFS($P$6:$P$14,$E$6:$E$14,8) -> 0 | O28: =SUMIFS($P$6:$P$14,$E$6:$E$14,9) -> 0 | P28: =SUMIFS($P$6:$P$14,$E$6:$E$14,10) -> 0
A29: Integration cost | B29: $ | C29: [A] | F29: =SUMIFS($Q$6:$Q$14,$E$6:$E$14,0) -> 175000 | G29: =SUMIFS($Q$6:$Q$14,$E$6:$E$14,1) -> 175000 | H29: =SUMIFS($Q$6:$Q$14,$E$6:$E$14,2) -> 175000 | I29: =SUMIFS($Q$6:$Q$14,$E$6:$E$14,3) -> 350000 | J29: =SUMIFS($Q$6:$Q$14,$E$6:$E$14,4) -> 175000 | K29: =SUMIFS($Q$6:$Q$14,$E$6:$E$14,5) -> 175000 | L29: =SUMIFS($Q$6:$Q$14,$E$6:$E$14,6) -> 175000 | M29: =SUMIFS($Q$6:$Q$14,$E$6:$E$14,7) -> 175000 | N29: =SUMIFS($Q$6:$Q$14,$E$6:$E$14,8) -> 0 | O29: =SUMIFS($Q$6:$Q$14,$E$6:$E$14,9) -> 0 | P29: =SUMIFS($Q$6:$Q$14,$E$6:$E$14,10) -> 0
A30: Transaction cost | B30: $ | C30: [A] | F30: =SUMIFS($R$6:$R$14,$E$6:$E$14,0) -> 255000 | G30: =SUMIFS($R$6:$R$14,$E$6:$E$14,1) -> 165000 | H30: =SUMIFS($R$6:$R$14,$E$6:$E$14,2) -> 165000 | I30: =SUMIFS($R$6:$R$14,$E$6:$E$14,3) -> 465000 | J30: =SUMIFS($R$6:$R$14,$E$6:$E$14,4) -> 165000 | K30: =SUMIFS($R$6:$R$14,$E$6:$E$14,5) -> 165000 | L30: =SUMIFS($R$6:$R$14,$E$6:$E$14,6) -> 165000 | M30: =SUMIFS($R$6:$R$14,$E$6:$E$14,7) -> 165000 | N30: =SUMIFS($R$6:$R$14,$E$6:$E$14,8) -> 0 | O30: =SUMIFS($R$6:$R$14,$E$6:$E$14,9) -> 0 | P30: =SUMIFS($R$6:$R$14,$E$6:$E$14,10) -> 0
A31: Senior leaders acquired | B31: FTE | C31: [A] | F31: =SUMIFS($S$6:$S$14,$E$6:$E$14,0) -> 2 | G31: =SUMIFS($S$6:$S$14,$E$6:$E$14,1) -> 1 | H31: =SUMIFS($S$6:$S$14,$E$6:$E$14,2) -> 1 | I31: =SUMIFS($S$6:$S$14,$E$6:$E$14,3) -> 3 | J31: =SUMIFS($S$6:$S$14,$E$6:$E$14,4) -> 1 | K31: =SUMIFS($S$6:$S$14,$E$6:$E$14,5) -> 1 | L31: =SUMIFS($S$6:$S$14,$E$6:$E$14,6) -> 1 | M31: =SUMIFS($S$6:$S$14,$E$6:$E$14,7) -> 1 | N31: =SUMIFS($S$6:$S$14,$E$6:$E$14,8) -> 0 | O31: =SUMIFS($S$6:$S$14,$E$6:$E$14,9) -> 0 | P31: =SUMIFS($S$6:$S$14,$E$6:$E$14,10) -> 0
A32: Senior leaders retained locally | B32: FTE | C32: [A] | F32: =SUMIFS($T$6:$T$14,$E$6:$E$14,0) -> 1 | G32: =SUMIFS($T$6:$T$14,$E$6:$E$14,1) -> 1 | H32: =SUMIFS($T$6:$T$14,$E$6:$E$14,2) -> 1 | I32: =SUMIFS($T$6:$T$14,$E$6:$E$14,3) -> 2 | J32: =SUMIFS($T$6:$T$14,$E$6:$E$14,4) -> 1 | K32: =SUMIFS($T$6:$T$14,$E$6:$E$14,5) -> 1 | L32: =SUMIFS($T$6:$T$14,$E$6:$E$14,6) -> 1 | M32: =SUMIFS($T$6:$T$14,$E$6:$E$14,7) -> 1 | N32: =SUMIFS($T$6:$T$14,$E$6:$E$14,8) -> 0 | O32: =SUMIFS($T$6:$T$14,$E$6:$E$14,9) -> 0 | P32: =SUMIFS($T$6:$T$14,$E$6:$E$14,10) -> 0
A33: Redundant senior leaders | B33: FTE | C33: [A] | F33: =SUMIFS($U$6:$U$14,$E$6:$E$14,0) -> 1 | G33: =SUMIFS($U$6:$U$14,$E$6:$E$14,1) -> 0 | H33: =SUMIFS($U$6:$U$14,$E$6:$E$14,2) -> 0 | I33: =SUMIFS($U$6:$U$14,$E$6:$E$14,3) -> 1 | J33: =SUMIFS($U$6:$U$14,$E$6:$E$14,4) -> 0 | K33: =SUMIFS($U$6:$U$14,$E$6:$E$14,5) -> 0 | L33: =SUMIFS($U$6:$U$14,$E$6:$E$14,6) -> 0 | M33: =SUMIFS($U$6:$U$14,$E$6:$E$14,7) -> 0 | N33: =SUMIFS($U$6:$U$14,$E$6:$E$14,8) -> 0 | O33: =SUMIFS($U$6:$U$14,$E$6:$E$14,9) -> 0 | P33: =SUMIFS($U$6:$U$14,$E$6:$E$14,10) -> 0
A34: Integration pods required | B34: pods | C34: [C] | F34: =IF(F19=0,0,CEILING(F19/INDEX(Assumptions!$D$84:$F$84,1,2),1)) -> 1 | G34: =IF(G19=0,0,CEILING(G19/INDEX(Assumptions!$D$84:$F$84,1,2),1)) -> 1 | H34: =IF(H19=0,0,CEILING(H19/INDEX(Assumptions!$D$84:$F$84,1,2),1)) -> 1 | I34: =IF(I19=0,0,CEILING(I19/INDEX(Assumptions!$D$84:$F$84,1,2),1)) -> 1 | J34: =IF(J19=0,0,CEILING(J19/INDEX(Assumptions!$D$84:$F$84,1,2),1)) -> 1 | K34: =IF(K19=0,0,CEILING(K19/INDEX(Assumptions!$D$84:$F$84,1,2),1)) -> 1 | L34: =IF(L19=0,0,CEILING(L19/INDEX(Assumptions!$D$84:$F$84,1,2),1)) -> 1 | M34: =IF(M19=0,0,CEILING(M19/INDEX(Assumptions!$D$84:$F$84,1,2),1)) -> 1 | ... P34: =IF(P19=0,0,CEILING(P19/INDEX(Assumptions!$D$84:$F$84,1,2),1)) -> 0
A35: Weighted market-support multiplier | B35: x | C35: [E] | F35: =IF(F22=0,1,SUMIFS($W$6:$W$14,$E$6:$E$14,0)/F22) -> 1 | G35: =IF(G22=0,1,SUMIFS($W$6:$W$14,$E$6:$E$14,1)/G22) -> 0.9 | H35: =IF(H22=0,1,SUMIFS($W$6:$W$14,$E$6:$E$14,2)/H22) -> 0.9 | I35: =IF(I22=0,1,SUMIFS($W$6:$W$14,$E$6:$E$14,3)/I22) -> 1.09375 | J35: =IF(J22=0,1,SUMIFS($W$6:$W$14,$E$6:$E$14,4)/J22) -> 0.9 | K35: =IF(K22=0,1,SUMIFS($W$6:$W$14,$E$6:$E$14,5)/K22) -> 1 | L35: =IF(L22=0,1,SUMIFS($W$6:$W$14,$E$6:$E$14,6)/L22) -> 0.9 | M35: =IF(M22=0,1,SUMIFS($W$6:$W$14,$E$6:$E$14,7)/M22) -> 0.9 | N35: =IF(N22=0,1,SUMIFS($W$6:$W$14,$E$6:$E$14,8)/N22) -> 1 | O35: =IF(O22=0,1,SUMIFS($W$6:$W$14,$E$6:$E$14,9)/O22) -> 1 | P35: =IF(P22=0,1,SUMIFS($W$6:$W$14,$E$6:$E$14,10)/P22) -> 1
A36: INDEPENDENT RECONSTRUCTION FROM PRIMITIVES (controls read these; none reads the column it is testing)
A37: Seller notes rebuilt from EV x share | B37: $ | C37: [C] | F37: =F26*INDEX(Assumptions!$D$98:$F$98,1,2) -> 900000 | G37: =G26*INDEX(Assumptions!$D$98:$F$98,1,2) -> 450000 | H37: =H26*INDEX(Assumptions!$D$98:$F$98,1,2) -> 450000 | I37: =I26*INDEX(Assumptions!$D$98:$F$98,1,2) -> 1575000 | J37: =J26*INDEX(Assumptions!$D$98:$F$98,1,2) -> 450000 | K37: =K26*INDEX(Assumptions!$D$98:$F$98,1,2) -> 450000 | L37: =L26*INDEX(Assumptions!$D$98:$F$98,1,2) -> 450000 | M37: =M26*INDEX(Assumptions!$D$98:$F$98,1,2) -> 450000 | ... P37: =P26*INDEX(Assumptions!$D$98:$F$98,1,2) -> 0
A38: Integration cost rebuilt from close count | B38: $ | C38: [C] | F38: =F19*INDEX(Assumptions!$D$63:$F$63,1,2) -> 175000 | G38: =G19*INDEX(Assumptions!$D$63:$F$63,1,2) -> 175000 | H38: =H19*INDEX(Assumptions!$D$63:$F$63,1,2) -> 175000 | I38: =I19*INDEX(Assumptions!$D$63:$F$63,1,2) -> 350000 | J38: =J19*INDEX(Assumptions!$D$63:$F$63,1,2) -> 175000 | K38: =K19*INDEX(Assumptions!$D$63:$F$63,1,2) -> 175000 | L38: =L19*INDEX(Assumptions!$D$63:$F$63,1,2) -> 175000 | M38: =M19*INDEX(Assumptions!$D$63:$F$63,1,2) -> 175000 | ... P38: =P19*INDEX(Assumptions!$D$63:$F$63,1,2) -> 0
A39: Transaction cost rebuilt from close count and EV | B39: $ | C39: [C] | F39: =F19*INDEX(Assumptions!$D$64:$F$64,1,2)+F26*INDEX(Assumptions!$D$65:$F$65,1,2) -> 255000 | G39: =G19*INDEX(Assumptions!$D$64:$F$64,1,2)+G26*INDEX(Assumptions!$D$65:$F$65,1,2) -> 165000 | H39: =H19*INDEX(Assumptions!$D$64:$F$64,1,2)+H26*INDEX(Assumptions!$D$65:$F$65,1,2) -> 165000 | I39: =I19*INDEX(Assumptions!$D$64:$F$64,1,2)+I26*INDEX(Assumptions!$D$65:$F$65,1,2) -> 465000 | J39: =J19*INDEX(Assumptions!$D$64:$F$64,1,2)+J26*INDEX(Assumptions!$D$65:$F$65,1,2) -> 165000 | K39: =K19*INDEX(Assumptions!$D$64:$F$64,1,2)+K26*INDEX(Assumptions!$D$65:$F$65,1,2) -> 165000 | L39: =L19*INDEX(Assumptions!$D$64:$F$64,1,2)+L26*INDEX(Assumptions!$D$65:$F$65,1,2) -> 165000 | M39: =M19*INDEX(Assumptions!$D$64:$F$64,1,2)+M26*INDEX(Assumptions!$D$65:$F$65,1,2) -> 165000 | ... P39: =P19*INDEX(Assumptions!$D$64:$F$64,1,2)+P26*INDEX(Assumptions!$D$65:$F$65,1,2) -> 0
A40: Roll-up versus reconstruction — must be nil | B40: $ | C40: [C] | F40: =ABS(F28-F37)+ABS(F29-F38)+ABS(F30-F39) -> 0 | G40: =ABS(G28-G37)+ABS(G29-G38)+ABS(G30-G39) -> 0 | H40: =ABS(H28-H37)+ABS(H29-H38)+ABS(H30-H39) -> 0 | I40: =ABS(I28-I37)+ABS(I29-I38)+ABS(I30-I39) -> 0 | J40: =ABS(J28-J37)+ABS(J29-J38)+ABS(J30-J39) -> 0 | K40: =ABS(K28-K37)+ABS(K29-K38)+ABS(K30-K39) -> 0 | L40: =ABS(L28-L37)+ABS(L29-L38)+ABS(L30-L39) -> 0 | M40: =ABS(M28-M37)+ABS(M29-M38)+ABS(M30-M39) -> 0 | ... P40: =ABS(P28-P37)+ABS(P29-P38)+ABS(P30-P39) -> 0
A41: Maximum reconstruction difference across all years | B41: $ | C41: [C] | F41: =MAX(F40:P40) -> 0
A42: PROGRAMME CONSTRAINT DIAGNOSTIC — cadence and the Year-7 managed-unit ceiling
A43: The ceiling is a Year-7 MANAGED-unit constraint, not a cap on cumulative units ever purchased. Attrition, change-of-control loss and vintage retention sit between the two, so gross acquired units are shown as a memo only.
...

Sheet Anchor QoE
A1: ANCHOR QoE AND CONTRACT DURABILITY
A2: Durability is underwritten on retained recurring revenue, contract rights, concentration and EBITDA contribution. No synthetic client gross profit is invented until a target GL supports direct cost allocation.
A4: Line | D4: Close | E4: Year 1 | F4: Year 2 | G4: Year 3 | H4: Year 4 | I4: Year 5 | J4: Year 6 | K4: Year 7 | L4: Year 8 | M4: Year 9 | N4: Year 10
A6: CONTRACT DURABILITY BY PMA CATEGORY
E7: Downside | F7: Base | G7: Upside | I7: Downside retention | J7: Base retention | K7: Upside retention
A8: Institutional owner | B8: % / % | C8: [C]/[A] | E8: =INDEX(Assumptions!$D$50:$F$50,1,1) -> 0.35 | F8: =INDEX(Assumptions!$D$50:$F$50,1,2) -> 0.35 | G8: =INDEX(Assumptions!$D$50:$F$50,1,3) -> 0.35 | I8: =INDEX(Assumptions!$D$51:$F$51,1,1) -> 0.85 | J8: =INDEX(Assumptions!$D$51:$F$51,1,2) -> 0.88 | K8: =INDEX(Assumptions!$D$51:$F$51,1,3) -> 0.91 | N8: 30-day termination without cause; assignment consent required
A9: Regional owner | B9: % / % | C9: [C]/[A] | E9: =INDEX(Assumptions!$D$52:$F$52,1,1) -> 0.4 | F9: =INDEX(Assumptions!$D$52:$F$52,1,2) -> 0.4 | G9: =INDEX(Assumptions!$D$52:$F$52,1,3) -> 0.4 | I9: =INDEX(Assumptions!$D$53:$F$53,1,1) -> 0.9 | J9: =INDEX(Assumptions!$D$53:$F$53,1,2) -> 0.92 | K9: =INDEX(Assumptions!$D$53:$F$53,1,3) -> 0.94 | N9: 60-90 day termination; change-of-control consent
A10: Developer / lease-up | B10: % / % | C10: [C]/[A] | E10: =INDEX(Assumptions!$D$54:$F$54,1,1) -> 0.25 | F10: =INDEX(Assumptions!$D$54:$F$54,1,2) -> 0.25 | G10: =INDEX(Assumptions!$D$54:$F$54,1,3) -> 0.25 | I10: =INDEX(Assumptions!$D$55:$F$55,1,1) -> 0.92 | J10: =INDEX(Assumptions!$D$55:$F$55,1,2) -> 0.94 | K10: =INDEX(Assumptions!$D$55:$F$55,1,3) -> 0.96 | N10: Term contract to stabilisation; assignment generally permitted
A11: Category shares sum to 100% | B11: % | C11: [C] | E11: =SUM(E8:E10) -> 1 | F11: =SUM(F8:F10) -> 1 | G11: =SUM(G8:G10) -> 1
A12: Blended annual revenue retention | B12: % | C12: [C] | E12: =SUMPRODUCT(E8:E10,I8:I10)/E11 -> 0.8875 | F12: =SUMPRODUCT(F8:F10,J8:J10)/F11 -> 0.911 | G12: =SUMPRODUCT(G8:G10,K8:K10)/G11 -> 0.9345
A13: Implied average contract life | B13: years | C13: [C] | E13: =IF(E12>=1,99,1/(1-E12)) -> 8.8888889 | F13: =IF(F12>=1,99,1/(1-F12)) -> 11.235955 | G13: =IF(G12>=1,99,1/(1-G12)) -> 15.267176
A14: Change-of-control loss at close | B14: % | C14: [A] | E14: =INDEX(Assumptions!$D$56:$F$56,1,1) -> 0.09 | F14: =INDEX(Assumptions!$D$56:$F$56,1,2) -> 0.06 | G14: =INDEX(Assumptions!$D$56:$F$56,1,3) -> 0.04
A16: ANCHOR ACQUISITION BASIS (at-close facts, frozen across cases)
A17: Normalized EBITDA at close | B17: $ / x | C17: [OQ] | D17: ='Acquisition Schedule'!$F$6 -> 1000000
A18: Recurring revenue at close | B18: $ / x | C18: [OQ] | D18: ='Acquisition Schedule'!$G$6 -> 5105335.5
A19: Normalized EBITDA margin | B19: $ / x | C19: [OQ] | D19: ='Acquisition Schedule'!$H$6 -> 0.19587351
A20: Units at close | B20: $ / x | C20: [OQ] | D20: ='Acquisition Schedule'!$I$6 -> 7812.5
A21: Properties at close | B21: $ / x | C21: [OQ] | D21: ='Acquisition Schedule'!$J$6 -> 31.25
A22: Clients at close | B22: $ / x | C22: [OQ] | D22: ='Acquisition Schedule'!$K$6 -> 6
A23: Entry multiple | B23: $ / x | C23: [OQ] | D23: ='Acquisition Schedule'!$M$6 -> 6
A24: Enterprise value | B24: $ / x | C24: [OQ] | D24: ='Acquisition Schedule'!$N$6 -> 6000000
A25: EV as a multiple of recurring revenue | B25: x | C25: [C] | D25: =D24/D18 -> 1.1752411
A26: Largest client share of acquired revenue | B26: % | C26: [OQ] | D26: =1/D22 -> 0.16666667 | N26: Equal-share proxy. Replace with the target client schedule.

Sheet Revenue & Durability
A1: REVENUE AND DURABILITY — VINTAGE RETENTION BY CASE
A2: Net factor = retention x (1 + standalone wins + platform uplift). New business is separated into what the target wins on its own capability, which is purchased, and what the platform adds, which is buyer-created and switches off with the evidence flag.
A3: Revenue, EBITDA margin and EBITDA reconcile by construction. Third-party pass-through sits in revenue and is excluded from EBITDA contribution.
A5: Line | D5: Close | E5: Year 1 | F5: Year 2 | G5: Year 3 | H5: Year 4 | I5: Year 5 | J5: Year 6 | K5: Year 7 | L5: Year 8 | M5: Year 9 | N5: Year 10
A7: DOWNSIDE
A8: Blended annual contract retention | B8: % | C8: [C] | D8: ='Anchor QoE'!E$12 -> 0.8875
A9: Gross annual contract churn | B9: % | C9: [C] | D9: =1-D8 -> 0.1125
A10: Gross new-business wins — target standalone capability | B10: % | C10: [C] | D10: =INDEX(Assumptions!$D$57:$F$57,1,1) -> 0.08
A11: Gross new-business wins — platform uplift | B11: % | C11: [A] | D11: =(INDEX(Assumptions!$D$58:$F$58,1,1)*(1-Assumptions!$D$8)) -> 0.02
A12: Net annual factor — standalone counterfactual | B12: x | C12: [C] | D12: =D8*(1+D10) -> 0.9585
A13: NET ANNUAL FACTOR INSIDE THE PLATFORM | B13: x | C13: [C] | D13: =D8*(1+D10+D11) -> 0.97625
A14: Platform growth advantage over standalone | B14: pts | C14: [A] | D14: =D13-D12 -> 0.01775
A15: Ownership must not make an acquired business grow more slowly than it would have alone. The advantage line is the platform contribution, and it can never be negative by construction because the uplift is additive.
A16: Close-year part-period factor | B16: % | C16: [C] | D16: =(1-INDEX(Assumptions!$D$56:$F$56,1,1))*INDEX(Assumptions!$D$20:$F$20,1,1) -> 0.455
A17: Not a retention rate. A deal closing mid-year contributes only part of a full year of EBITDA in its close year, and the book that survives change of control is smaller. Half a year of ownership at 94 percent surviving change of control gives 47 percent of a full year. The anchor is grossed back to a full year because it is owned from day one.
